Workbook
Name Slicer_Company_Name: #N/A
Name Slicer_Year: #N/A

Sheet Sources
A1: S. No | B1: Details of Assumptions/Data Point | C1: Assumed Figure | D1: Remarks | E1: URL
A2: 1 | B2: Actual Financial Statement data for last 7 years | D2: Financial statements has been taken for the last seven years from capitaline database | E2: https://awsone.capitaline.com/index.html#/Company/Condensed/condensed?section=ProfitLoss
A3: 2 | B3: Revenue Growth | C3: 0.1398
A4: 3 | B4: Tax Rate | C4: 0.25 | D4: Varun Beverages Annual Report 2025
A5: 4 | B5: Risk free Rate (Rf) | C5: 0.0667 | D5: 10-year Indian Government bond yield used as proxy for risk-free rate | E5: https://in.investing.com/rates-bonds/india-10-year-bond-yield-historical-data?utm_source
A6: 5 | B6: Market Risk (Rm) | C6: 0.1276313 | D6: Average long-term return of Indian stock market (NIFTY 50) used as market return
B7: Market Risk Premium (Rp= Rm-Rf) | C7: =C6-C5 -> 0.060931297 | D7: Market risk premium calculated as difference between market return and risk-free rate
A8: 6 | B8: Terminal Growth Rate | C8: 0.05 | D8: Terminal growth rate assumed based on long-term GDP growth and pharmaceutical industry growth | E8: https://data.worldbank.org/indicator/NY.GDP.MKTP.KD.ZG
A9: 7 | B9: Varun Beverages Stock Data | D9: Historical stock price data used for Beta calculation | E9: https://www.bseindia.com/
A10: 8 | B10: NIFTY 50 data | D10: Market index data used for Beta calculation | E10: https://www.bseindia.com/
A11: 9 | B11: Current Market Price | C11: 420 | D11: Latest market price from stock exchange | E11: https://awsone.capitaline.com/index.html#/Company/General/CompanyInfo

Sheet Company Overview
A1: VARUN BEVERAGES LIMITED — COMPANY OVERVIEW
A3: ABOUT THE COMPANY | D3: Business Segments of Varun Beverages Limited
A4: Company Name | B4: Varun Beverages Limited | D4: Segment | E4: Key Brands / Products | F4: Business Description
A5: Listing | B5: NSE / BSE | D5: Carbonated Soft Drinks (CSD) | E5: Pepsi, Mountain Dew, 7UP, Mirinda, Slice, Sting | F5: Largest revenue segment. VBL manufactures, distributes and sells PepsiCo CSD brands across licensed territories. CSD drives volume and forms the core franchise.
A6: Sector | B6: Consumer Staples – Beverages | D6: Energy Drinks | E6: Sting Energy Drink | F6: Fastest-growing segment. Sting has achieved mass-market penetration at an accessible price point, becoming a significant volume & margin driver for VBL.
A7: Industry | B7: Non-Alcoholic Beverages (FMCG) | D7: Packaged Drinking Water | E7: Aquafina | F7: High-volume, low-margin segment providing distribution reach and franchise complementarity. Growing with urbanisation and health trends.
A8: Founded | B8: 1995 | D8: Juices & Dairy | E8: Tropicana, Tropicana Juices, Lipton Iced Tea | F8: Health & wellness-oriented segment catering to urban, premium consumers. Supports premiumisation strategy and portfolio diversification.
A9: Headquarters | B9: Gurugram, Haryana, India | D9: Sports & Functional | E9: Gatorade, Other Functional Beverages | F9: Niche but growing category with high realization per unit. Targets fitness-oriented consumers in gyms, sports clubs and modern trade.
A10: Promoter / Parent | B10: Ravi Jaipuria Group (RJ Corp) | D10: International Operations | E10: Full PepsiCo portfolio across 7 countries | F10: Zambia, Zimbabwe, Sri Lanka, Nepal, Morocco, South Africa, Lesotho & Mozambique. International diversification provides revenue stability and growth optionality.
A11: Market Cap | B11: ~Rs. 1.15 Lakh Crore (Apr 2026)
A12: PepsiCo Franchisee | B12: Largest bottler of PepsiCo in India
A13: Geographies | B13: India, Sri Lanka, Nepal, Zambia, Zimbabwe, Morocco, South Africa, Lesotho, Mozambique | D13: Growth Drivers – Varun Beverages Limited
A14: Key Products | B14: Pepsi, Mountain Dew, 7UP, Mirinda, Tropicana, Gatorade, Aquafina, Sting Energy, Lipton | D14: Growth Driver | E14: Explanation | F14: Valuation Significance
D15: India Beverages Market Underpenetration | E15: Per-capita beverage consumption in India is <10% of developed markets. Rising incomes, urbanisation and heat intensity drive structurally higher volumes. | F15: Supports double-digit revenue growth assumptions over the medium term.
A16: Varun Beverages Limited (VBL) is PepsiCo's largest franchisee bottler outside the USA, with a dominant market position across 22 Indian states and 7 international territories. VBL's structural growth is driven by India's under-penetrated beverages market, premiumisation of product mix, rapid rural distribution expansion, and addition of high-growth energy drinks (Sting). Strong brand backing from PepsiCo, improving EBITDA margins, and deleveraging balance sheet position VBL as a compounding growth story. Key risks include commodity inflation (PET, sugar), seasonal demand concentration, and forex volatility in international markets. | D16: Sting Energy Drink Expansion | E16: Sting priced at ₹20/₹30 has created mass-market energy drink adoption. Volume CAGR of 40%+ since launch, now a top-3 SKU for VBL. | F16: Margin-accretive growth; higher realization and brand equity uplift.
D17: Rural Distribution Deepening | E17: VBL has invested heavily in direct coverage routes, cooler placements and last-mile infrastructure, unlocking a large and underserved rural population. | F17: Drives volume growth and increases competitive moat via distribution density.
D18: Premiumisation & Portfolio Width | E18: Increasing Tropicana, Gatorade and value-added health beverage contribution improves revenue per case and reduces CSD cyclicality. | F18: Supports margin expansion and revenue quality improvement over time.
A19: Key Financial Highlights (FY2025) | D19: International Market Scale-up | E19: New territories in South Africa, Morocco and Mozambique are in investment phase. Scale benefits expected over 3–5 years as franchisee network matures. | F19: Provides revenue diversification and reduces India-season concentration risk.
A20: Revenue (INR Cr.) | B20: 14,557 | D20: Capacity Expansion & Operating Leverage | E20: VBL continues to commission new greenfield and brownfield plants ahead of demand, enabling volume absorption at lower incremental cost. | F20: EBITDA margin improvement as fixed costs spread over higher volumes.
A21: EBITDA (INR Cr.) | B21: 4,279 | D21: Franchise Relationship with PepsiCo | E21: Exclusive long-term franchise agreements across territories provide revenue visibility and entry barrier. PepsiCo brand investment benefits VBL directly. | F21: Reduces competitive risk and supports brand-driven pricing power.
A22: EBITDA Margin | B22: 29.4% | D22: Brand Loyalty & Summer Seasonality Buffer | E22: Strong PepsiCo brand recall across price points ensures repeat purchase. Large summer season backlog creates predictable revenue visibility. | F22: Reduces earnings volatility and supports investor confidence in forecasts.
A23: PAT (INR Cr.) | B23: 2,677
A24: PAT Margin | B24: 18.4%
A25: EPS (INR) | B25: 7.91 | D25: Economic Moat — Varun Beverages Limited
A26: ROCE | B26: 28.5% | D26: Varun Beverages Limited possesses a durable economic moat rooted in exclusive PepsiCo franchise rights across high-population territories, a capital-intensive distribution infrastructure that is difficult and costly for competitors to replicate, and deep brand equity derived from PepsiCo's global portfolio. VBL's integrated supply chain – from concentrate sourcing through bottling, distribution and in-store activation – creates significant operational barriers to entry. The company's scale advantages in raw material procurement (PET resin, sugar, concentrate) further widen cost efficiencies relative to smaller regional players. The franchise relationship with PepsiCo Inc. acts as a regulatory and competitive moat, as new entrants cannot access the same brand portfolio in licensed geographies. Sting Energy's mass-market adoption at a disruptive price point reinforces VBL's ability to create new demand categories within its existing distribution architecture, compounding the competitive advantage of scale and brand.
A27: ROE | B27: 16.8%
A28: Net Debt / EBITDA | B28: 0.09x

Sheet Raw Data
B1: VARUN BEVERAGES LIMITED – RAW FINANCIAL DATA (SOURCE)
B2: Income Statement & Balance Sheet | INR in Crores | Source: Capitaline Database
C3: ACTUAL PERIOD
C4: FY2020 | D4: FY2021 | E4: FY2022 | F4: FY2023 | G4: FY2024 | H4: FY2025
B5: INCOME STATEMENT
B6: Year
B7: INCOME :
B8: Sales Turnover | C8: 4876.45 | D8: 6595.74 | E8: 10595.83 | F8: 12632.83 | G8: 14348.6 | H8: 14556.82
B9: Excise Duty | C9: 0 | D9: 0 | E9: 0 | F9: 0 | G9: 0 | H9: 0
B10: Net Sales | C10: 4876.45 | D10: 6595.74 | E10: 10595.83 | F10: 12632.83 | G10: 14348.6 | H10: 14556.82
B11: Other Income | C11: 71.99 | D11: 57.3 | E11: 143.76 | F11: 146.14 | G11: 353.94 | H11: 513.93
B12: Stock Adjustments | C12: 3.14 | D12: 76.07 | E12: 302.35 | F12: 61.82 | G12: -38.84 | H12: -12.97
B13: Total Income | C13: 4951.58 | D13: 6729.11 | E13: 11041.94 | F13: 12840.79 | G13: 14663.7 | H13: 15057.78
B14: EXPENDITURE :
B15: Raw Materials (Net) | C15: 2218.81 | D15: 3205.24 | E15: 5579.49 | F15: 6052.21 | G15: 6565.14 | H15: 6742.35
B16: Opening Stock of Raw Materials | C16: 265.17 | D16: 252.54 | E16: 558.19 | F16: 579.98 | G16: 590.58 | H16: 746.94
B17: Purchases of Raw Material | C17: 2277.92 | D17: 3695.64 | E17: 6115.66 | F17: 6104.51 | G17: 6620.24 | H17: 6562.24
B18: Purchase of Trading Goods | C18: 87.48 | D18: 119.43 | E18: 120.18 | F18: 149.43 | G18: 202.91 | H18: 140.45
B19: Direct Expense on Purchase/Adj | C19: -159.22 | D19: -304.18 | E19: -634.57 | F19: -191.13 | G19: -101.65 | H19: -25.07
B20: Closing Stock of Raw Materials | C20: 252.54 | D20: 558.19 | E20: 579.98 | F20: 590.58 | G20: 746.94 | H20: 682.21
B21: Adjustment on Amalgamation | C21: 0 | D21: 0 | E21: 0 | F21: 0 | G21: 0 | H21: 0
B22: Power & Fuel Cost | C22: 203.07 | D22: 258.39 | E22: 388.97 | F22: 436.94 | G22: 475.66 | H22: 474.54
B23: Employee Cost | C23: 695.06 | D23: 741.12 | E23: 920.47 | F23: 1036.8 | G23: 1177.55 | H23: 1260.22
B24: Salaries, Wages & Bonus | C24: 639.95 | D24: 678.45 | E24: 842.37 | F24: 942.3 | G24: 1058.03 | H24: 1147.22
B25: Contribution to Funds | C25: 33.67 | D25: 35.49 | E25: 39.8 | F25: 49.85 | G25: 59.2 | H25: 64.43
B26: Staff Welfare Expenses | C26: 21.45 | D26: 27.18 | E26: 35.39 | F26: 38.32 | G26: 46.3 | H26: 46.26
... B59: DPS (Adjusted) | C59: 0.22 | D59: 0.33 | E59: 0.7 | F59: 1 | G59: 1 | H59: 1.5
B62: BALANCE SHEET
C63: ACTUAL PERIOD
C64: FY2020 | D64: FY2021 | E64: FY2022 | F64: FY2023 | G64: FY2024 | H64: FY2025
B65: EQUITY & LIABILITIES
B66: Shareholders' Funds
B67: Share Capital | C67: 288.69 | D67: 433.03 | E67: 649.55 | F67: 649.61 | G67: 676.3 | H67: 676.4
B68: Reserves and Surplus | C68: 3723.08 | D68: 3965.59 | E68: 4867.85 | F68: 6425.85 | G68: 15882.4 | H68: 18088.13
B69: Total Shareholder's Fund | C69: 4011.77 | D69: 4398.62 | E69: 5517.4 | F69: 7075.45 | G69: 16558.71 | H69: 18764.53
B70: Share Application Money | C70: 0 | D70: 0 | E70: 0 | F70: 0.35 | G70: 0 | H70: 0.27
B71: Non-Current Liabilities
B72: Long-Term Borrowings | C72: 1954.35 | D72: 1712.44 | E72: 1653.26 | F72: 3010.55 | G72: 144.21 | H72: 266.39
B73: Lease Liabilities (NC) | C73: 0 | D73: 8.75 | E73: 111.74 | F73: 104.37 | G73: 41.96 | H73: 25.54
B74: Deferred Tax Liabilities (Net) | C74: 220.99 | D74: 298.18 | E74: 319.98 | F74: 313.33 | G74: 383.35 | H74: 493.22
...

Sheet Assumptions
B1: VARUN BEVERAGES LIMITED – ASSUMPTIONS SHEET
K3: Scenarios: | M3: Y-o-Y Growth
B4: Select Case | C4: Case 2 | K4: Case 1 | L4: Optimistic Case | M4: 0.14
K5: Case 2 | L5: Base Case | M5: 0.12
K6: Case 3 | L6: Worst Case | M6: 0.1
B9: P&L ASSUMPTIONS
C10: ACTUAL PERIOD | I10: FORECAST PERIOD
B11: Particulars | C11: FY2020 | D11: FY2021 | E11: FY2022 | F11: FY2023 | G11: FY2024 | H11: FY2025 | I11: FY2026E | J11: FY2027E | K11: FY2028E | L11: FY2029E | M11: FY2030E
B13: Net Sales / Revenue from Operations (INR Cr.) | C13: ='Raw Data'!C10 -> 4876.45 | D13: ='Raw Data'!D10 -> 6595.74 | E13: ='Raw Data'!E10 -> 10595.83 | F13: ='Raw Data'!F10 -> 12632.83 | G13: ='Raw Data'!G10 -> 14348.6 | H13: ='Raw Data'!H10 -> 14556.82 | I13: =H13*(1+I14) -> 16303.638 | J13: =I13*(1+J14) -> 18260.075 | K13: =J13*(1+K14) -> 20451.284 | L13: =K13*(1+L14) -> 22905.438 | M13: =L13*(1+M14) -> 25654.091
B14: Revenue Growth % (y-o-y) | C14: - | D14: =(D13-C13)/C13 -> 0.35257 | E14: =(E13-D13)/D13 -> 0.60646569 | F14: =(F13-E13)/E13 -> 0.19224544 | G14: =(G13-F13)/F13 -> 0.13581834 | H14: =(H13-G13)/G13 -> 0.01451152 | I14: =VLOOKUP($C$4,$K$4:$M$6,3,FALSE) -> 0.12 | J14: =VLOOKUP($C$4,$K$4:$M$6,3,FALSE) -> 0.12 | K14: =VLOOKUP($C$4,$K$4:$M$6,3,FALSE) -> 0.12 | L14: =VLOOKUP($C$4,$K$4:$M$6,3,FALSE) -> 0.12 | M14: =VLOOKUP($C$4,$K$4:$M$6,3,FALSE) -> 0.12
B15: Other Income (% of Net Sales) | C15: ='Raw Data'!C11/'Raw Data'!C10 -> 0.014762789 | D15: ='Raw Data'!D11/'Raw Data'!D10 -> 0.0086874255 | E15: ='Raw Data'!E11/'Raw Data'!E10 -> 0.013567602 | F15: ='Raw Data'!F11/'Raw Data'!F10 -> 0.011568271 | G15: ='Raw Data'!G11/'Raw Data'!G10 -> 0.024667215 | H15: ='Raw Data'!H11/'Raw Data'!H10 -> 0.035305101 | I15: =AVERAGE(C15:H15) -> 0.018093067 | J15: =AVERAGE(C15:H15) -> 0.018093067 | K15: =AVERAGE(C15:H15) -> 0.018093067 | L15: =AVERAGE(C15:H15) -> 0.018093067 | M15: =AVERAGE(C15:H15) -> 0.018093067
B16: Raw Material Cost (% of Net Sales) | C16: ='Raw Data'!C15/'Raw Data'!C10 -> 0.45500518 | D16: ='Raw Data'!D15/'Raw Data'!D10 -> 0.48595609 | E16: ='Raw Data'!E15/'Raw Data'!E10 -> 0.52657413 | F16: ='Raw Data'!F15/'Raw Data'!F10 -> 0.47908584 | G16: ='Raw Data'!G15/'Raw Data'!G10 -> 0.45754568 | H16: ='Raw Data'!H15/'Raw Data'!H10 -> 0.46317465 | I16: =AVERAGE(C16:H16) -> 0.47789026 | J16: =AVERAGE(C16:H16) -> 0.47789026 | K16: =AVERAGE(C16:H16) -> 0.47789026 | L16: =AVERAGE(C16:H16) -> 0.47789026 | M16: =AVERAGE(C16:H16) -> 0.47789026
B17: Power & Fuel Cost (% of Net Sales) | C17: ='Raw Data'!C22/'Raw Data'!C10 -> 0.041642998 | D17: ='Raw Data'!D22/'Raw Data'!D10 -> 0.039175286 | E17: ='Raw Data'!E22/'Raw Data'!E10 -> 0.036709724 | F17: ='Raw Data'!F22/'Raw Data'!F10 -> 0.034587658 | G17: ='Raw Data'!G22/'Raw Data'!G10 -> 0.033150273 | H17: ='Raw Data'!H22/'Raw Data'!H10 -> 0.032599153 | I17: =AVERAGE(C17:H17) -> 0.036310849 | J17: =AVERAGE(C17:H17) -> 0.036310849 | K17: =AVERAGE(C17:H17) -> 0.036310849 | L17: =AVERAGE(C17:H17) -> 0.036310849 | M17: =AVERAGE(C17:H17) -> 0.036310849
B18: Employee Cost (% of Net Sales) | C18: ='Raw Data'!C23/'Raw Data'!C10 -> 0.14253402 | D18: ='Raw Data'!D23/'Raw Data'!D10 -> 0.11236343 | E18: ='Raw Data'!E23/'Raw Data'!E10 -> 0.086870967 | F18: ='Raw Data'!F23/'Raw Data'!F10 -> 0.082071871 | G18: ='Raw Data'!G23/'Raw Data'!G10 -> 0.08206724 | H18: ='Raw Data'!H23/'Raw Data'!H10 -> 0.086572479 | I18: =AVERAGE(C18:H18) -> 0.098746668 | J18: =AVERAGE(C18:H18) -> 0.098746668 | K18: =AVERAGE(C18:H18) -> 0.098746668 | L18: =AVERAGE(C18:H18) -> 0.098746668 | M18: =AVERAGE(C18:H18) -> 0.098746668
B19: Other Mfg Expenses (% of Net Sales) | C19: ='Raw Data'!C30/'Raw Data'!C10 -> 0.038119944 | D19: ='Raw Data'!D30/'Raw Data'!D10 -> 0.038267124 | E19: ='Raw Data'!E30/'Raw Data'!E10 -> 0.036625729 | F19: ='Raw Data'!F30/'Raw Data'!F10 -> 0.032712385 | G19: ='Raw Data'!G30/'Raw Data'!G10 -> 0.034257001 | H19: ='Raw Data'!H30/'Raw Data'!H10 -> 0.030980667 | I19: =AVERAGE(C19:H19) -> 0.035160475 | J19: =AVERAGE(C19:H19) -> 0.035160475 | K19: =AVERAGE(C19:H19) -> 0.035160475 | L19: =AVERAGE(C19:H19) -> 0.035160475 | M19: =AVERAGE(C19:H19) -> 0.035160475
B20: Selling & Admin Expenses (% of Net Sales) | C20: ='Raw Data'!C31/'Raw Data'!C10 -> 0.14091398 | D20: ='Raw Data'!D31/'Raw Data'!D10 -> 0.14848069 | E20: ='Raw Data'!E31/'Raw Data'!E10 -> 0.12759737 | F20: ='Raw Data'!F31/'Raw Data'!F10 -> 0.12956083 | G20: ='Raw Data'!G31/'Raw Data'!G10 -> 0.12255481 | H20: ='Raw Data'!H31/'Raw Data'!H10 -> 0.12001728 | I20: =AVERAGE(C20:H20) -> 0.13152083 | J20: =AVERAGE(C20:H20) -> 0.13152083 | K20: =AVERAGE(C20:H20) -> 0.13152083 | L20: =AVERAGE(C20:H20) -> 0.13152083 | M20: =AVERAGE(C20:H20) -> 0.13152083
B21: Miscellaneous Expenses (% of Net Sales) | C21: ='Raw Data'!C32/'Raw Data'!C10 -> 0.019715162 | D21: ='Raw Data'!D32/'Raw Data'!D10 -> 0.0083265866 | E21: ='Raw Data'!E32/'Raw Data'!E10 -> 0.0084155748 | F21: ='Raw Data'!F32/'Raw Data'!F10 -> 0.01060095 | G21: ='Raw Data'!G32/'Raw Data'!G10 -> 0.010724391 | H21: ='Raw Data'!H32/'Raw Data'!H10 -> 0.0071272435 | I21: =AVERAGE(C21:H21) -> 0.010818318 | J21: =AVERAGE(C21:H21) -> 0.010818318 | K21: =AVERAGE(C21:H21) -> 0.010818318 | L21: =AVERAGE(C21:H21) -> 0.010818318 | M21: =AVERAGE(C21:H21) -> 0.010818318
B22: Depreciation Rate (% of Opening Gross Block) | C22: ='Raw Data'!C38/'Raw Data'!C91 -> 0.077855017 | D22: ='Raw Data'!D38/'Raw Data'!D91 -> 0.072834617 | E22: ='Raw Data'!E38/'Raw Data'!E91 -> 0.076787125 | F22: ='Raw Data'!F38/'Raw Data'!F91 -> 0.060878226 | G22: ='Raw Data'!G38/'Raw Data'!G91 -> 0.06093108 | H22: ='Raw Data'!H38/'Raw Data'!H91 -> 0.063986256 | I22: =AVERAGE(D22:H22) -> 0.067083461 | J22: =AVERAGE(D22:H22) -> 0.067083461 | K22: =AVERAGE(D22:H22) -> 0.067083461 | L22: =AVERAGE(D22:H22) -> 0.067083461 | M22: =AVERAGE(D22:H22) -> 0.067083461
B23: Interest / Finance Cost (% of Total Borrowings) | C23: ='Raw Data'!C36/('Raw Data'!C72+'Raw Data'!C81) -> 0.09650989 | D23: ='Raw Data'!D36/('Raw Data'!D72+'Raw Data'!D81) -> 0.049332193 | E23: ='Raw Data'!E36/('Raw Data'!E72+'Raw Data'!E81) -> 0.044967381 | F23: ='Raw Data'!F36/('Raw Data'!F72+'Raw Data'!F81) -> 0.051353855 | G23: ='Raw Data'!G36/('Raw Data'!G72+'Raw Data'!G81) -> 0.42523511 | H23: ='Raw Data'!H36/('Raw Data'!H72+'Raw Data'!H81) -> 0.088334619 | I23: =AVERAGE(C23:H23) -> 0.12595551 | J23: =AVERAGE(C23:H23) -> 0.12595551 | K23: =AVERAGE(C23:H23) -> 0.12595551 | L23: =AVERAGE(C23:H23) -> 0.12595551 | M23: =AVERAGE(C23:H23) -> 0.12595551
B24: Tax Rate (% of PBT) | C24: ='Raw Data'!C40/'Raw Data'!C39 -> 0.14027038 | D24: ='Raw Data'!D40/'Raw Data'!D39 -> 0.17129107 | E24: ='Raw Data'!E40/'Raw Data'!E39 -> 0.23461561 | F24: ='Raw Data'!F40/'Raw Data'!F39 -> 0.25293477 | G24: ='Raw Data'!G40/'Raw Data'!G39 -> 0.22363955 | H24: ='Raw Data'!H40/'Raw Data'!H39 -> 0.21549143 | I24: =AVERAGE(C24:H24) -> 0.2063738 | J24: =AVERAGE(C24:H24) -> 0.2063738 | K24: =AVERAGE(C24:H24) -> 0.2063738 | L24: =AVERAGE(C24:H24) -> 0.2063738 | M24: =AVERAGE(C24:H24) -> 0.2063738
B25: Dividend Payout Ratio (% of Reported Net Profit) | C25: ='Raw Data'!C49/'Raw Data'!C43 -> 0.31872985 | D25: ='Raw Data'!D49/'Raw Data'!D43 -> 0.22116897 | E25: ='Raw Data'!E49/'Raw Data'!E43 -> 0.12784601 | F25: ='Raw Data'!F49/'Raw Data'!F43 -> 0.12807513 | G25: ='Raw Data'!G49/'Raw Data'!G43 -> 0 | H25: ='Raw Data'!H49/'Raw Data'!H43 -> 0.18952119 | I25: =AVERAGE(F25:H25) -> 0.10586544 | J25: =AVERAGE(F25:H25) -> 0.10586544 | K25: =AVERAGE(F25:H25) -> 0.10586544 | L25: =AVERAGE(F25:H25) -> 0.10586544 | M25: =AVERAGE(F25:H25) -> 0.10586544
B27: BALANCE SHEET ASSUMPTIONS (WORKING CAPITAL)
C28: ACTUAL PERIOD | I28: FORECAST PERIOD
B29: Particulars | C29: FY2020 | D29: FY2021 | E29: FY2022 | F29: FY2023 | G29: FY2024 | H29: FY2025 | I29: FY2026E | J29: FY2027E | K29: FY2028E | L29: FY2029E | M29: FY2030E
B31: Inventory Days (Inventories / Raw Mat Cost × 365) | C31: ='Raw Data'!C106/'Raw Data'!C15*365 -> 111.70713 | D31: ='Raw Data'!D106/'Raw Data'!D15*365 -> 121.42259 | E31: ='Raw Data'!E106/'Raw Data'!E15*365 -> 93.296117 | F31: ='Raw Data'!F106/'Raw Data'!F15*365 -> 92.62609 | G31: ='Raw Data'!G106/'Raw Data'!G15*365 -> 93.886673 | H31: ='Raw Data'!H106/'Raw Data'!H15*365 -> 89.812298 | I31: =AVERAGE(C31:H31) -> 100.45848 | J31: =AVERAGE(C31:H31) -> 100.45848 | K31: =AVERAGE(C31:H31) -> 100.45848 | L31: =AVERAGE(C31:H31) -> 100.45848 | M31: =AVERAGE(C31:H31) -> 100.45848
B32: Debtor Days / Days Receivable (Trade Rec / Net Sales × 365) | C32: ='Raw Data'!C107/'Raw Data'!C10*365 -> 12.764091 | D32: ='Raw Data'!D107/'Raw Data'!D10*365 -> 7.3085886 | E32: ='Raw Data'!E107/'Raw Data'!E10*365 -> 5.1753945 | F32: ='Raw Data'!F107/'Raw Data'!F10*365 -> 6.1524694 | G32: ='Raw Data'!G107/'Raw Data'!G10*365 -> 5.0814992 | H32: ='Raw Data'!H107/'Raw Data'!H10*365 -> 6.6749915 | I32: =AVERAGE(C32:H32) -> 7.192839 | J32: =AVERAGE(C32:H32) -> 7.192839 | K32: =AVERAGE(C32:H32) -> 7.192839 | L32: =AVERAGE(C32:H32) -> 7.192839 | M32: =AVERAGE(C32:H32) -> 7.192839
B33: Creditor Days (Trade Payables / Raw Mat Cost × 365) | C33: ='Raw Data'!C83/'Raw Data'!C15*365 -> 44.756221 | D33: ='Raw Data'!D83/'Raw Data'!D15*365 -> 52.776984 | E33: ='Raw Data'!E83/'Raw Data'!E15*365 -> 37.667125 | F33: ='Raw Data'!F83/'Raw Data'!F15*365 -> 29.663363 | G33: ='Raw Data'!G83/'Raw Data'!G15*365 -> 31.013497 | H33: ='Raw Data'!H83/'Raw Data'!H15*365 -> 24.249423 | I33: =AVERAGE(C33:H33) -> 36.687769 | J33: =AVERAGE(C33:H33) -> 36.687769 | K33: =AVERAGE(C33:H33) -> 36.687769 | L33: =AVERAGE(C33:H33) -> 36.687769 | M33: =AVERAGE(C33:H33) -> 36.687769
B34: Capex (% of Net Sales) | C34: - | D34: =('Raw Data'!D91-'Raw Data'!C91+'Raw Data'!D38)/'Raw Data'!D10 -> 0.088992289 | E34: =('Raw Data'!E91-'Raw Data'!D91+'Raw Data'!E38)/'Raw Data'!E10 -> 0.12130999 | F34: =('Raw Data'!F91-'Raw Data'!E91+'Raw Data'!F38)/'Raw Data'!F10 -> 0.21695297 | G34: =('Raw Data'!G91-'Raw Data'!F91+'Raw Data'!G38)/'Raw Data'!G10 -> 0.15644941 | H34: =('Raw Data'!H91-'Raw Data'!G91+'Raw Data'!H38)/'Raw Data'!H10 -> 0.10572089 | I34: =AVERAGE(D34:H34) -> 0.13788511 | J34: =AVERAGE(D34:H34) -> 0.13788511 | K34: =AVERAGE(D34:H34) -> 0.13788511 | L34: =AVERAGE(D34:H34) -> 0.13788511 | M34: =AVERAGE(D34:H34) -> 0.13788511
B35: Long-Term Borrowings (INR Cr.) – Scheduled Repayment | C35: ='Raw Data'!C72 -> 1954.35 | D35: ='Raw Data'!D72 -> 1712.44 | E35: ='Raw Data'!E72 -> 1653.26 | F35: ='Raw Data'!F72 -> 3010.55 | G35: ='Raw Data'!G72 -> 144.21 | H35: ='Raw Data'!H72 -> 266.39 | I35: =MAX(H35*0.85,0) -> 226.4315 | J35: =MAX(I35*0.85,0) -> 192.46677 | K35: =MAX(J35*0.85,0) -> 163.59676 | L35: =MAX(K35*0.85,0) -> 139.05724 | M35: =MAX(L35*0.85,0) -> 118.19866
B36: Short-Term Borrowings (INR Cr.) – Scheduled Repayment | C36: ='Raw Data'!C81 -> 635.54 | D36: ='Raw Data'!D81 -> 1456.89 | E36: ='Raw Data'!E81 -> 1818.59 | F36: ='Raw Data'!F81 -> 1749.56 | G36: ='Raw Data'!G81 -> 687.33 | H36: ='Raw Data'!H81 -> 109.68 | I36: =MAX(H36*0.8,0) -> 87.744 | J36: =MAX(I36*0.8,0) -> 70.1952 | K36: =MAX(J36*0.8,0) -> 56.15616 | L36: =MAX(K36*0.8,0) -> 44.924928 | M36: =MAX(L36*0.8,0) -> 35.939942

Sheet Financial Statements
B1: VARUN BEVERAGES LIMITED – PROJECTED FINANCIAL STATEMENTS
B2: INR in Crores | Actual FY2020–FY2025 | Forecast FY2026–FY2030
B4: INCOME STATEMENT
C5: ACTUAL PERIOD | I5: FORECAST PERIOD
B6: Particulars (INR Cr.) | C6: FY2020 | D6: FY2021 | E6: FY2022 | F6: FY2023 | G6: FY2024 | H6: FY2025 | I6: FY2026E | J6: FY2027E | K6: FY2028E | L6: FY2029E | M6: FY2030E
B8: Net Sales / Revenue from Operations | C8: ='Raw Data'!C10 -> 4876.45 | D8: ='Raw Data'!D10 -> 6595.74 | E8: ='Raw Data'!E10 -> 10595.83 | F8: ='Raw Data'!F10 -> 12632.83 | G8: ='Raw Data'!G10 -> 14348.6 | H8: ='Raw Data'!H10 -> 14556.82 | I8: =Assumptions!I13 -> 16303.638 | J8: =Assumptions!J13 -> 18260.075 | K8: =Assumptions!K13 -> 20451.284 | L8: =Assumptions!L13 -> 22905.438 | M8: =Assumptions!M13 -> 25654.091
B9: Other Income | C9: ='Raw Data'!C11 -> 71.99 | D9: ='Raw Data'!D11 -> 57.3 | E9: ='Raw Data'!E11 -> 143.76 | F9: ='Raw Data'!F11 -> 146.14 | G9: ='Raw Data'!G11 -> 353.94 | H9: ='Raw Data'!H11 -> 513.93 | I9: =I8*Assumptions!I15 -> 294.98282 | J9: =J8*Assumptions!J15 -> 330.38076 | K9: =K8*Assumptions!K15 -> 370.02645 | L9: =L8*Assumptions!L15 -> 414.42963 | M9: =M8*Assumptions!M15 -> 464.16118
B10: Stock Adjustments | C10: ='Raw Data'!C12 -> 3.14 | D10: ='Raw Data'!D12 -> 76.07 | E10: ='Raw Data'!E12 -> 302.35 | F10: ='Raw Data'!F12 -> 61.82 | G10: ='Raw Data'!G12 -> -38.84 | H10: ='Raw Data'!H12 -> -12.97 | I10: =0 -> 0 | J10: =0 -> 0 | K10: =0 -> 0 | L10: =0 -> 0 | M10: =0 -> 0
B11: Total Income | C11: ='Raw Data'!C13 -> 4951.58 | D11: ='Raw Data'!D13 -> 6729.11 | E11: ='Raw Data'!E13 -> 11041.94 | F11: ='Raw Data'!F13 -> 12840.79 | G11: ='Raw Data'!G13 -> 14663.7 | H11: ='Raw Data'!H13 -> 15057.78 | I11: =I8+I9+I10 -> 16598.621 | J11: =J8+J9+J10 -> 18590.456 | K11: =K8+K9+K10 -> 20821.31 | L11: =L8+L9+L10 -> 23319.868 | M11: =M8+M9+M10 -> 26118.252
B13: EXPENDITURE
B14: Raw Material Cost | C14: ='Raw Data'!C15 -> 2218.81 | D14: ='Raw Data'!D15 -> 3205.24 | E14: ='Raw Data'!E15 -> 5579.49 | F14: ='Raw Data'!F15 -> 6052.21 | G14: ='Raw Data'!G15 -> 6565.14 | H14: ='Raw Data'!H15 -> 6742.35 | I14: =I8*Assumptions!I16 -> 7791.35 | J14: =J8*Assumptions!J16 -> 8726.312 | K14: =K8*Assumptions!K16 -> 9773.4695 | L14: =L8*Assumptions!L16 -> 10946.286 | M14: =M8*Assumptions!M16 -> 12259.84
B15: Power & Fuel Cost | C15: ='Raw Data'!C22 -> 203.07 | D15: ='Raw Data'!D22 -> 258.39 | E15: ='Raw Data'!E22 -> 388.97 | F15: ='Raw Data'!F22 -> 436.94 | G15: ='Raw Data'!G22 -> 475.66 | H15: ='Raw Data'!H22 -> 474.54 | I15: =I8*Assumptions!I17 -> 591.99895 | J15: =J8*Assumptions!J17 -> 663.03882 | K15: =K8*Assumptions!K17 -> 742.60348 | L15: =L8*Assumptions!L17 -> 831.7159 | M15: =M8*Assumptions!M17 -> 931.5218
B16: Employee Cost | C16: ='Raw Data'!C23 -> 695.06 | D16: ='Raw Data'!D23 -> 741.12 | E16: ='Raw Data'!E23 -> 920.47 | F16: ='Raw Data'!F23 -> 1036.8 | G16: ='Raw Data'!G23 -> 1177.55 | H16: ='Raw Data'!H23 -> 1260.22 | I16: =I8*Assumptions!I18 -> 1609.93 | J16: =J8*Assumptions!J18 -> 1803.1216 | K16: =K8*Assumptions!K18 -> 2019.4962 | L16: =L8*Assumptions!L18 -> 2261.8357 | M16: =M8*Assumptions!M18 -> 2533.256
B17: Other Manufacturing Expenses | C17: ='Raw Data'!C30 -> 185.89 | D17: ='Raw Data'!D30 -> 252.4 | E17: ='Raw Data'!E30 -> 388.08 | F17: ='Raw Data'!F30 -> 413.25 | G17: ='Raw Data'!G30 -> 491.54 | H17: ='Raw Data'!H30 -> 450.98 | I17: =I8*Assumptions!I19 -> 573.24367 | J17: =J8*Assumptions!J19 -> 642.03291 | K17: =K8*Assumptions!K19 -> 719.07686 | L17: =L8*Assumptions!L19 -> 805.36608 | M17: =M8*Assumptions!M19 -> 902.01001
B18: Selling & Administration Expenses | C18: ='Raw Data'!C31 -> 687.16 | D18: ='Raw Data'!D31 -> 979.34 | E18: ='Raw Data'!E31 -> 1352 | F18: ='Raw Data'!F31 -> 1636.72 | G18: ='Raw Data'!G31 -> 1758.49 | H18: ='Raw Data'!H31 -> 1747.07 | I18: =I8*Assumptions!I20 -> 2144.268 | J18: =J8*Assumptions!J20 -> 2401.5802 | K18: =K8*Assumptions!K20 -> 2689.7698 | L18: =L8*Assumptions!L20 -> 3012.5422 | M18: =M8*Assumptions!M20 -> 3374.0473
B19: Miscellaneous Expenses | C19: ='Raw Data'!C32 -> 96.14 | D19: ='Raw Data'!D32 -> 54.92 | E19: ='Raw Data'!E32 -> 89.17 | F19: ='Raw Data'!F32 -> 133.92 | G19: ='Raw Data'!G32 -> 153.88 | H19: ='Raw Data'!H32 -> 103.75 | I19: =I8*Assumptions!I21 -> 176.37794 | J19: =J8*Assumptions!J21 -> 197.5433 | K19: =K8*Assumptions!K21 -> 221.24849 | L19: =L8*Assumptions!L21 -> 247.79831 | M19: =M8*Assumptions!M21 -> 277.53411
B20: Total Expenditure (ex-Int, ex-Dep) | C20: ='Raw Data'!C34 -> 4086.13 | D20: ='Raw Data'!D34 -> 5491.4 | E20: ='Raw Data'!E34 -> 8718.17 | F20: ='Raw Data'!F34 -> 9709.83 | G20: ='Raw Data'!G34 -> 10622.25 | H20: ='Raw Data'!H34 -> 10778.91 | I20: =I14+I15+I16+I17+I18+I19 -> 12887.169 | J20: =J14+J15+J16+J17+J18+J19 -> 14433.629 | K20: =K14+K15+K16+K17+K18+K19 -> 16165.664 | L20: =L14+L15+L16+L17+L18+L19 -> 18105.544 | M20: =M14+M15+M16+M17+M18+M19 -> 20278.209
B22: EBITDA (Operating Profit) | C22: ='Raw Data'!C35 -> 865.45 | D22: ='Raw Data'!D35 -> 1237.71 | E22: ='Raw Data'!E35 -> 2323.75 | F22: ='Raw Data'!F35 -> 3130.94 | G22: ='Raw Data'!G35 -> 4041.45 | H22: ='Raw Data'!H35 -> 4278.89 | I22: =I11-I20 -> 3711.4526 | J22: =J11-J20 -> 4156.827 | K22: =K11-K20 -> 4655.6462 | L22: =L11-L20 -> 5214.3237 | M22: =M11-M20 -> 5840.0426
B23: EBITDA Margin % | C23: =C22/C8 -> 0.17747542 | D23: =D22/D8 -> 0.18765294 | E23: =E22/E8 -> 0.21930797 | F23: =F22/F8 -> 0.24784154 | G23: =G22/G8 -> 0.28166163 | H23: =H22/H8 -> 0.29394401 | I23: =I22/I8 -> 0.22764567 | J23: =J22/J8 -> 0.22764567 | ... M23: =M22/M8 -> 0.22764567
B25: Less: Depreciation | C25: ='Raw Data'!C38 -> 412.82 | D25: ='Raw Data'!D38 -> 399.83 | E25: ='Raw Data'!E38 -> 483.13 | F25: ='Raw Data'!F38 -> 518.33 | G25: ='Raw Data'!G38 -> 617.91 | H25: ='Raw Data'!H38 -> 702.42 | I25: ='PPE Schedule'!I21 -> 839.65886 | J25: ='PPE Schedule'!J21 -> 990.46442 | K25: ='PPE Schedule'!K21 -> 1159.3666 | L25: ='PPE Schedule'!L21 -> 1348.5371 | M25: ='PPE Schedule'!M21 -> 1560.4081
B26: EBIT (Gross Profit) | C26: ='Raw Data'!C37 -> 615.5 | D26: ='Raw Data'!D37 -> 1081.36 | E26: ='Raw Data'!E37 -> 2167.63 | F26: ='Raw Data'!F37 -> 2886.49 | G26: ='Raw Data'!G37 -> 3687.85 | H26: ='Raw Data'!H37 -> 4245.67 | I26: =I22-I25 -> 2871.7938 | J26: =J22-J25 -> 3166.3625 | K26: =K22-K25 -> 3496.2795 | L26: =L22-L25 -> 3865.7866 | M26: =M22-M25 -> 4279.6345
B27: EBIT Margin % | C27: =C26/C8 -> 0.12621887 | D27: =D26/D8 -> 0.16394825 | E27: =E26/E8 -> 0.20457387 | F27: =F26/F8 -> 0.22849116 | G27: =G26/G8 -> 0.25701811 | H27: =H26/H8 -> 0.29166192 | I27: =I26/I8 -> 0.17614435 | J27: =J26/J8 -> 0.17340359 | ... M27: =M26/M8 -> 0.16682074
B29: Less: Interest / Finance Cost | C29: ='Raw Data'!C36 -> 249.95 | D29: ='Raw Data'!D36 -> 156.35 | E29: ='Raw Data'!E36 -> 156.12 | F29: ='Raw Data'!F36 -> 244.45 | G29: ='Raw Data'!G36 -> 353.6 | H29: ='Raw Data'!H36 -> 33.22 | I29: =(Assumptions!I35+Assumptions!I36)*Assumptions!I23 -> 39.572134 | J29: =(Assumptions!J35+Assumptions!J36)*Assumptions!J23 -> 33.083722 | K29: =(Assumptions!K35+Assumptions!K36)*Assumptions!K23 -> 27.67909 | L29: =(Assumptions!L35+Assumptions!L36)*Assumptions!L23 -> 23.173568 | M29: =(Assumptions!M35+Assumptions!M36)*Assumptions!M23 -> 19.414606
B30: Profit Before Tax (PBT) | C30: ='Raw Data'!C39 -> 202.68 | D30: ='Raw Data'!D39 -> 681.53 | E30: ='Raw Data'!E39 -> 1684.5 | F30: ='Raw Data'!F39 -> 2368.16 | G30: ='Raw Data'!G39 -> 3069.94 | H30: ='Raw Data'!H39 -> 3543.25 | I30: =I26-I29 -> 2832.2216 | J30: =J26-J29 -> 3133.2788 | K30: =K26-K29 -> 3468.6004 | L30: =L26-L29 -> 3842.613 | M30: =M26-M29 -> 4260.2199
B31: Less: Tax | C31: ='Raw Data'!C40 -> 28.43 | D31: ='Raw Data'!D40 -> 116.74 | E31: ='Raw Data'!E40 -> 395.21 | F31: ='Raw Data'!F40 -> 598.99 | G31: ='Raw Data'!G40 -> 686.56 | H31: ='Raw Data'!H40 -> 763.54 | I31: =I30*Assumptions!I24 -> 584.49634 | J31: =J30*Assumptions!J24 -> 646.62666 | K31: =K30*Assumptions!K24 -> 715.82826 | L31: =L30*Assumptions!L24 -> 793.01465 | M31: =M30*Assumptions!M24 -> 879.19776
B32: Reported Net Profit (PAT) | C32: ='Raw Data'!C43 -> 226.43 | D32: ='Raw Data'!D43 -> 489.49 | E32: ='Raw Data'!E43 -> 1270.2 | F32: ='Raw Data'!F43 -> 1775.13 | G32: ='Raw Data'!G43 -> 2320.36 | H32: ='Raw Data'!H43 -> 2676.64 | I32: =I30-I31 -> 2247.7253 | J32: =J30-J31 -> 2486.6522 | K32: =K30-K31 -> 2752.7722 | L32: =L30-L31 -> 3049.5984 | M32: =M30-M31 -> 3381.0221
B33: PAT Margin % | C33: =C32/C8 -> 0.046433369 | D33: =D32/D8 -> 0.074213053 | E33: =E32/E8 -> 0.11987735 | F33: =F32/F8 -> 0.14051721 | G33: =G32/G8 -> 0.16171334 | H33: =H32/H8 -> 0.18387532 | I33: =I32/I8 -> 0.13786648 | J33: =J32/J8 -> 0.13617973 | ... M33: =M32/M8 -> 0.13179271
B34: Less: Dividend / Appropriations | C34: ='Raw Data'!C49 -> 72.17 | D34: ='Raw Data'!D49 -> 108.26 | E34: ='Raw Data'!E49 -> 162.39 | F34: ='Raw Data'!F49 -> 227.35 | G34: ='Raw Data'!G49 -> 0 | H34: ='Raw Data'!H49 -> 507.28 | I34: =I32*Assumptions!I25 -> 237.95643 | J34: =J32*Assumptions!J25 -> 263.25052 | K34: =K32*Assumptions!K25 -> 291.42344 | L34: =L32*Assumptions!L25 -> 322.84707 | M34: =M32*Assumptions!M25 -> 357.93339
B35: Retained Earnings (Added to Reserves) | C35: =C32-C34 -> 154.26 | D35: =D32-D34 -> 381.23 | E35: =E32-E34 -> 1107.81 | F35: =F32-F34 -> 1547.78 | G35: =G32-G34 -> 2320.36 | H35: =H32-H34 -> 2169.36 | I35: =I32-I34 -> 2009.7689 | J35: =J32-J34 -> 2223.4016 | ... M35: =M32-M34 -> 3023.0887
B37: EPS – Reported (INR) | C37: ='Raw Data'!C55 -> 7.84 | D37: ='Raw Data'!D55 -> 11.3 | E37: ='Raw Data'!E55 -> 19.56 | F37: ='Raw Data'!F55 -> 13.66 | G37: ='Raw Data'!G55 -> 6.86 | H37: ='Raw Data'!H55 -> 7.91 | I37: =I32/'Raw Data'!H43*'Raw Data'!H55 -> 6.6424723 | J37: =J32/'Raw Data'!H43*'Raw Data'!H55 -> 7.3485484 | K37: =K32/'Raw Data'!H43*'Raw Data'!H55 -> 8.1349857 | L37: =L32/'Raw Data'!H43*'Raw Data'!H55 -> 9.0121656 | M37: =M32/'Raw Data'!H43*'Raw Data'!H55 -> 9.9915883
B40: BALANCE SHEET
C41: ACTUAL PERIOD | I41: FORECAST PERIOD
B42: Particulars (INR Cr.) | C42: FY2020 | D42: FY2021 | E42: FY2022 | F42: FY2023 | G42: FY2024 | H42: FY2025 | I42: FY2026E | J42: FY2027E | K42: FY2028E | L42: FY2029E | M42: FY2030E
B44: EQUITY & LIABILITIES
B45: Share Capital | C45: ='Raw Data'!C67 -> 288.69 | D45: ='Raw Data'!D67 -> 433.03 | E45: ='Raw Data'!E67 -> 649.55 | F45: ='Raw Data'!F67 -> 649.61 | G45: ='Raw Data'!G67 -> 676.3 | H45: ='Raw Data'!H67 -> 676.4 | I45: =H45 -> 676.4 | J45: =H45 -> 676.4 | K45: =H45 -> 676.4 | L45: =H45 -> 676.4 | M45: =H45 -> 676.4
B46: Reserves & Surplus | C46: ='Raw Data'!C68 -> 3723.08 | D46: ='Raw Data'!D68 -> 3965.59 | E46: ='Raw Data'!E68 -> 4867.85 | F46: ='Raw Data'!F68 -> 6425.85 | G46: ='Raw Data'!G68 -> 15882.4 | H46: ='Raw Data'!H68 -> 18088.13 | I46: =H46+I35 -> 20097.899 | J46: =I46+J35 -> 22321.301 | K46: =J46+K35 -> 24782.649 | L46: =K46+L35 -> 27509.401 | M46: =L46+M35 -> 30532.489
B47: Total Shareholders' Equity | C47: ='Raw Data'!C69 -> 4011.77 | D47: ='Raw Data'!D69 -> 4398.62 | E47: ='Raw Data'!E69 -> 5517.4 | F47: ='Raw Data'!F69 -> 7075.45 | G47: ='Raw Data'!G69 -> 16558.71 | H47: ='Raw Data'!H69 -> 18764.53 | I47: =I45+I46 -> 20774.299 | J47: =J45+J46 -> 22997.701 | K47: =K45+K46 -> 25459.049 | L47: =L45+L46 -> 28185.801 | M47: =M45+M46 -> 31208.889
B48: Long-Term Borrowings | C48: ='Raw Data'!C72 -> 1954.35 | D48: ='Raw Data'!D72 -> 1712.44 | E48: ='Raw Data'!E72 -> 1653.26 | F48: ='Raw Data'!F72 -> 3010.55 | G48: ='Raw Data'!G72 -> 144.21 | H48: ='Raw Data'!H72 -> 266.39 | I48: =Assumptions!I35 -> 226.4315 | J48: =Assumptions!J35 -> 192.46677 | K48: =Assumptions!K35 -> 163.59676 | L48: =Assumptions!L35 -> 139.05724 | M48: =Assumptions!M35 -> 118.19866
B49: Deferred Tax Liabilities (Net) | C49: ='Raw Data'!C74 -> 220.99 | D49: ='Raw Data'!D74 -> 298.18 | E49: ='Raw Data'!E74 -> 319.98 | F49: ='Raw Data'!F74 -> 313.33 | G49: ='Raw Data'!G74 -> 383.35 | H49: ='Raw Data'!H74 -> 493.22 | I49: =H49 -> 493.22 | J49: =H49 -> 493.22 | K49: =H49 -> 493.22 | L49: =H49 -> 493.22 | M49: =H49 -> 493.22
B50: Other Long-Term Liabilities & Provisions | C50: ='Raw Data'!C77+'Raw Data'!C78 -> 201.84 | D50: ='Raw Data'!D77+'Raw Data'!D78 -> 200.13 | E50: ='Raw Data'!E77+'Raw Data'!E78 -> 198.25 | F50: ='Raw Data'!F77+'Raw Data'!F78 -> 212.47 | G50: ='Raw Data'!G77+'Raw Data'!G78 -> 182.43 | H50: ='Raw Data'!H77+'Raw Data'!H78 -> 173.19 | I50: =H50 -> 173.19 | J50: =H50 -> 173.19 | K50: =H50 -> 173.19 | L50: =H50 -> 173.19 | M50: =H50 -> 173.19
...

Sheet PPE Schedule
B1: VARUN BEVERAGES LIMITED – PPE SCHEDULE
B2: Property, Plant & Equipment Roll-forward | INR in Crores
B4: PPE ROLL-FORWARD SCHEDULE
C5: ACTUAL PERIOD | I5: FORECAST PERIOD
B6: Particulars (INR Cr.) | C6: FY2020 | D6: FY2021 | E6: FY2022 | F6: FY2023 | G6: FY2024 | H6: FY2025 | I6: FY2026E | J6: FY2027E | K6: FY2028E | L6: FY2029E | M6: FY2030E
B8: Revenue from Operations (linked from FS) | C8: ='Financial Statements'!C8 -> 4876.45 | D8: ='Financial Statements'!D8 -> 6595.74 | E8: ='Financial Statements'!E8 -> 10595.83 | F8: ='Financial Statements'!F8 -> 12632.83 | G8: ='Financial Statements'!G8 -> 14348.6 | H8: ='Financial Statements'!H8 -> 14556.82 | I8: ='Financial Statements'!I8 -> 16303.638 | J8: ='Financial Statements'!J8 -> 18260.075 | ... M8: ='Financial Statements'!M8 -> 25654.091
B10: Opening Gross Block | C10: ='Raw Data'!C91 -> 5302.42 | D10: ='Raw Data'!D91 -> 5489.56 | E10: ='Raw Data'!E91 -> 6291.81 | F10: ='Raw Data'!F91 -> 8514.21 | G10: ='Raw Data'!G91 -> 10141.13 | H10: ='Raw Data'!H91 -> 10977.67 | I10: =H13 -> 12516.63 | J10: =I13 -> 14764.659 | K10: =J13 -> 17282.451 | L10: =K13 -> 20102.379 | M10: =L13 -> 23260.698
B11: Add: Capex (linked from Assumptions) | C11: 0 | D11: ='Raw Data'!D91-'Raw Data'!C91+'Raw Data'!D38 -> 586.97 | E11: ='Raw Data'!E91-'Raw Data'!D91+'Raw Data'!E38 -> 1285.38 | F11: ='Raw Data'!F91-'Raw Data'!E91+'Raw Data'!F38 -> 2740.73 | G11: ='Raw Data'!G91-'Raw Data'!F91+'Raw Data'!G38 -> 2244.83 | H11: ='Raw Data'!H91-'Raw Data'!G91+'Raw Data'!H38 -> 1538.96 | I11: ='Financial Statements'!I8*Assumptions!I34 -> 2248.029 | J11: ='Financial Statements'!J8*Assumptions!J34 -> 2517.7924 | K11: ='Financial Statements'!K8*Assumptions!K34 -> 2819.9275 | L11: ='Financial Statements'!L8*Assumptions!L34 -> 3158.3188 | M11: ='Financial Statements'!M8*Assumptions!M34 -> 3537.3171
B12: Less: Disposals / Write-offs | C12: 0 | D12: 0 | E12: 0 | F12: 0 | G12: 0 | H12: 0 | I12: 0 | J12: 0 | K12: 0 | L12: 0 | M12: 0
B13: Closing Gross Block | C13: =C10+C11-C12 -> 5302.42 | D13: =D10+D11-D12 -> 6076.53 | E13: =E10+E11-E12 -> 7577.19 | F13: =F10+F11-F12 -> 11254.94 | G13: =G10+G11-G12 -> 12385.96 | H13: =H10+H11-H12 -> 12516.63 | I13: =I10+I11-I12 -> 14764.659 | J13: =J10+J11-J12 -> 17282.451 | ... M13: =M10+M11-M12 -> 26798.015
B15: Opening Accumulated Depreciation | C15: ='Raw Data'!C91-'Raw Data'!C92 -> 596.25 | D15: ='Raw Data'!D91-'Raw Data'!D92 -> 1554.65 | E15: ='Raw Data'!E91-'Raw Data'!E92 -> 1916.44 | F15: ='Raw Data'!F91-'Raw Data'!F92 -> 3010.6 | G15: ='Raw Data'!G91-'Raw Data'!G92 -> 2439.52 | H15: ='Raw Data'!H91-'Raw Data'!H92 -> 1602.34 | I15: =H18 -> 0 | J15: =I18 -> 0 | K15: =J18 -> 0 | L15: =K18 -> 0 | M15: =L18 -> 0
B16: Add: Depreciation for the Year | C16: ='Raw Data'!C38 -> 412.82 | D16: ='Raw Data'!D38 -> 399.83 | E16: ='Raw Data'!E38 -> 483.13 | F16: ='Raw Data'!F38 -> 518.33 | G16: ='Raw Data'!G38 -> 617.91 | H16: ='Raw Data'!H38 -> 702.42 | I16: =I10*Assumptions!I22 -> 839.65886 | J16: =J10*Assumptions!J22 -> 990.46442 | K16: =K10*Assumptions!K22 -> 1159.3666 | L16: =L10*Assumptions!L22 -> 1348.5371 | M16: =M10*Assumptions!M22 -> 1560.4081
B17: Closing Accumulated Depreciation | C17: =C15+C16 -> 1009.07 | D17: =D15+D16 -> 1954.48 | E17: =E15+E16 -> 2399.57 | F17: =F15+F16 -> 3528.93 | G17: =G15+G16 -> 3057.43 | H17: =H15+H16 -> 2304.76 | I17: =I15+I16 -> 839.65886 | J17: =J15+J16 -> 990.46442 | ... M17: =M15+M16 -> 1560.4081
B19: Net PPE / Net Book Value (Closing) | C19: =C13-C17 -> 4293.35 | D19: =D13-D17 -> 4122.05 | E19: =E13-E17 -> 5177.62 | F19: =F13-F17 -> 7726.01 | G19: =G13-G17 -> 9328.53 | H19: =H13-H17 -> 10211.87 | I19: =I13-I17 -> 13925 | J19: =J13-J17 -> 16291.987 | ... M19: =M13-M17 -> 25237.607
B21: Depreciation for the Year (same as above) | C21: =C16 -> 412.82 | D21: =D16 -> 399.83 | E21: =E16 -> 483.13 | F21: =F16 -> 518.33 | G21: =G16 -> 617.91 | H21: =H16 -> 702.42 | I21: =I16 -> 839.65886 | J21: =J16 -> 990.46442 | ... M21: =M16 -> 1560.4081
B23: Capex (% of Revenue) – Actual/Forecast | D23: =D11/D8 -> 0.088992289 | E23: =E11/E8 -> 0.12130999 | F23: =F11/F8 -> 0.21695297 | G23: =G11/G8 -> 0.15644941 | H23: =H11/H8 -> 0.10572089 | I23: =Assumptions!I34 -> 0.13788511 | J23: =Assumptions!J34 -> 0.13788511 | K23: =Assumptions!K34 -> 0.13788511 | L23: =Assumptions!L34 -> 0.13788511 | M23: =Assumptions!M34 -> 0.13788511
B24: Depreciation Rate (% of Opening Gross Block) | D24: =D16/D10 -> 0.072834617 | E24: =E16/E10 -> 0.076787125 | F24: =F16/F10 -> 0.060878226 | G24: =G16/G10 -> 0.06093108 | H24: =H16/H10 -> 0.063986256 | I24: =Assumptions!I22 -> 0.067083461 | J24: =Assumptions!J22 -> 0.067083461 | K24: =Assumptions!K22 -> 0.067083461 | L24: =Assumptions!L22 -> 0.067083461 | M24: =Assumptions!M22 -> 0.067083461

Sheet Beta
A1: BETA
A2: VARUN BEVERAGES | E2: BSE SENSEX
A3: Date | B3: Close Price | C3: Return % | E3: Date | F3: SENSEX | G3: Return % | I3: BETA : Market Risk
A4: 42675 | B4: 436.55 | E4: 42675 | F4: 26652.81 | I4: 10 Year Beta Computation
A5: 42705 | B5: 381.35 | C5: =LN(B5/B4) -> -0.13518533 | E5: 42705 | F5: 26626.46 | G5: =LN(F5/F4) -> -0.00098912775
A6: 42736 | B6: 399.45 | C6: =LN(B6/B5) -> 0.046371012 | E6: 42736 | F6: 27655.96 | G6: =LN(F6/F5) -> 0.037935798 | I6: Using SLOPE Function | J6: =SLOPE(C5:C117,G5:G117) -> 1.20182
A7: 42767 | B7: 388.65 | C7: =LN(B7/B6) -> -0.027409405 | E7: 42767 | F7: 28743.32 | G7: =LN(F7/F6) -> 0.038564136
A8: 42795 | B8: 404.75 | C8: =LN(B8/B7) -> 0.040590397 | E8: 42795 | F8: 29620.5 | G8: =LN(F8/F7) -> 0.030061297
A9: 42826 | B9: 470.85 | C9: =LN(B9/B8) -> 0.15126998 | E9: 42826 | F9: 29918.4 | G9: =LN(F9/F8) -> 0.010006987
A10: 42856 | B10: 497.55 | C10: =LN(B10/B9) -> 0.055156482 | E10: 42856 | F10: 31145.8 | G10: =LN(F10/F9) -> 0.040205729 | I10: Performance VS Market
A11: 42887 | B11: 533.55 | C11: =LN(B11/B10) -> 0.069856733 | E11: 42887 | F11: 30921.61 | G11: =LN(F11/F10) -> -0.0072241125
A12: 42917 | B12: 500.2 | C12: =LN(B12/B11) -> -0.064544769 | E12: 42917 | F12: 32514.94 | G12: =LN(F12/F11) -> 0.050244384 | I12: Cipla Ltd. | J12: =AVERAGE(C5:C2272) -> -0.00068792561
A13: 42948 | B13: 524.3 | C13: =LN(B13/B12) -> 0.047056021 | E13: 42948 | F13: 31730.49 | G13: =LN(F13/F12) -> -0.024421628 | I13: BSE Sensex | J13: =AVERAGE(G5:G2272) -> 0.0089551566
A14: 42979 | B14: 505.8 | C14: =LN(B14/B13) -> -0.035922705 | E14: 42979 | F14: 31283.72 | G14: =LN(F14/F13) -> -0.014180214
A15: 43009 | B15: 501.25 | C15: =LN(B15/B14) -> -0.0090363556 | E15: 43009 | F15: 33213.13 | G15: =LN(F15/F14) -> 0.059847445
A16: 43040 | B16: 509.3 | C16: =LN(B16/B15) -> 0.015932255 | E16: 43040 | F16: 33149.35 | G16: =LN(F16/F15) -> -0.0019221711
A17: 43070 | B17: 651.35 | C17: =LN(B17/B16) -> 0.2460099 | E17: 43070 | F17: 34056.83 | G17: =LN(F17/F16) -> 0.027007491
A18: 43101 | B18: 691.05 | C18: =LN(B18/B17) -> 0.059165048 | E18: 43101 | F18: 35965.02 | G18: =LN(F18/F17) -> 0.0545162
A19: 43132 | B19: 649.05 | C19: =LN(B19/B18) -> -0.062702425 | E19: 43132 | F19: 34184.04 | G19: =LN(F19/F18) -> -0.050787931
A20: 43160 | B20: 617.4 | C20: =LN(B20/B19) -> -0.049992643 | E20: 43160 | F20: 32968.68 | G20: =LN(F20/F19) -> -0.036200849
A21: 43191 | B21: 652.2 | C21: =LN(B21/B20) -> 0.054834151 | E21: 43191 | F21: 35160.36 | G21: =LN(F21/F20) -> 0.064361292
A22: 43221 | B22: 766.35 | C22: =LN(B22/B21) -> 0.16128772 | E22: 43221 | F22: 35322.38 | G22: =LN(F22/F21) -> 0.0045974457
A23: 43252 | B23: 753.25 | C23: =LN(B23/B22) -> -0.017241806 | E23: 43252 | F23: 35423.48 | G23: =LN(F23/F22) -> 0.0028581197
A24: 43282 | B24: 752.3 | C24: =LN(B24/B23) -> -0.0012619974 | E24: 43282 | F24: 37606.58 | G24: =LN(F24/F23) -> 0.059804158
A25: 43313 | B25: 816.7 | C25: =LN(B25/B24) -> 0.08213665 | E25: 43313 | F25: 38645.07 | G25: =LN(F25/F24) -> 0.027240177
... A117: 46113 | B117: 403.9 | C117: =LN(B117/B116) -> 0.05039457 | E117: 46113 | F117: 73319.55 | G117: =LN(F117/F116) -> 0.018889904

Sheet WACC
A1: Weighted Average Cost of Capital
A4: Capital Structure
A5: Total Debt | B5: ='Financial Statements'!H48+'Financial Statements'!H52 -> 376.07
A6: Total Equity | B6: ='Financial Statements'!H47 -> 18764.53
A7: Total Mix | B7: =SUM(B5:B6) -> 19140.6
A8: % of debt | B8: =B5/B7 -> 0.019647764
A9: % of Equity | B9: =B6/B7 -> 0.98035224
A10: Debt to Equity | B10: =B5/B6 -> 0.020041536
A12: Cost Of Equity
A13: Risk Free Rate(Rf) | B13: =Sources!C5 -> 0.0667
A14: Beta | B14: =Beta!J6 -> 1.20182
A15: Market Risk Premium | B15: =Sources!C7 -> 0.060931297
A16: Cost Of Equity | B16: =B13+B14*B15 -> 0.13992845
A18: Cost Of Debt
A19: Cost Of Debt | B19: ='Financial Statements'!H29/'Financial Statements'!H48 -> 0.12470438
A20: Tax Rate | B20: =Sources!C4 -> 0.25
A21: Cost Of Debt after tax | B21: =B19*(1-B20) -> 0.093528286
A23: WACC
A24: Source | B24: Weight | C24: Cost | D24: Weighted Cost
A25: Debt | B25: =B8 -> 0.019647764 | C25: =B21 -> 0.093528286 | D25: =B25*C25 -> 0.0018376217
A26: Equity | B26: =B9 -> 0.98035224 | C26: =B16 -> 0.13992845 | D26: =B26*C26 -> 0.13717917
A27: WACC | D27: =SUM(D25:D26) -> 0.13901679

Sheet DCF
A1: DCF Valuation
A4: Assumtions/Base
A5: Tax Rate | B5: =Sources!C4 -> 0.25
A6: Discount Rate (WACC) | B6: =WACC!D27 -> 0.13901679
A7: Perpetural Growth Rate | B7: =Sources!C8 -> 0.05
A8: Valuation Date | B8: 46112
A9: Last Fiscal Year End | B9: 45747
A10: Current Market Price | B10: =Sources!C11 -> 420
A11: Total Shares Outstanding (in Cr.) | B11: ='Financial Statements'!H45 -> 676.4
A12: Debt (in Cr.) | B12: ='Financial Statements'!H48 -> 266.39
A13: Cash (in Cr.) | B13: ='Financial Statements'!H65 -> 1599.94
G15: INR Cr.
A16: Discounted Cash Flows
A17: YEARS | B17: 1 | C17: 2 | D17: 3 | E17: 4 | F17: 5 | G17: Growth | J17: INTRINSIC VALUE
A18: Particulars | B18: 2026 | C18: 2027 | D18: 2028 | E18: 2029 | F18: 2030 | G18: Terminal Value | J18: PV of Cash Flows | K18: =B29+C29+D29+E29+F29 -> 4595.8981
A19: EBIT | B19: ='Financial Statements'!I26 -> 2871.7938 | C19: ='Financial Statements'!J26 -> 3166.3625 | D19: ='Financial Statements'!K26 -> 3496.2795 | E19: ='Financial Statements'!L26 -> 3865.7866 | F19: ='Financial Statements'!M26 -> 4279.6345 | J19: Continuing Value | K19: =G25 -> 16847.814
A20: Tax Rate | B20: =$B$5 -> 0.25 | C20: =$B$5 -> 0.25 | D20: =$B$5 -> 0.25 | E20: =$B$5 -> 0.25 | F20: =$B$5 -> 0.25 | J20: PV of contuning value | K20: =G29 -> 8788.0582
A21: NOPAT | B21: =B19*(1-B20) -> 2153.8453 | C21: =C19*(1-C20) -> 2374.7719 | D21: =D19*(1-D20) -> 2622.2097 | E21: =E19*(1-E20) -> 2899.3399 | F21: =F19*(1-F20) -> 3209.7259 | J21: Enterprise Value (in Cr) | K21: =K20+K18 -> 13383.956
A22: Add- Depreciation | B22: ='Financial Statements'!I25 -> 839.65886 | C22: ='Financial Statements'!J25 -> 990.46442 | D22: ='Financial Statements'!K25 -> 1159.3666 | E22: ='Financial Statements'!L25 -> 1348.5371 | F22: ='Financial Statements'!M25 -> 1560.4081 | J22: Less: Debt (in Cr) | K22: =B12 -> 266.39
A23: Less-Capex | B23: ='PPE Schedule'!H11 -> 1538.96 | C23: ='PPE Schedule'!I11 -> 2248.029 | D23: ='PPE Schedule'!J11 -> 2517.7924 | E23: ='PPE Schedule'!K11 -> 2819.9275 | F23: ='PPE Schedule'!L11 -> 3158.3188 | J23: Add: Cash (in Cr) | K23: =B13 -> 1599.94
A24: Less-Net Changes In WC | B24: ='Financial Statements'!I85-'Financial Statements'!H85 -> -100.29576 | C24: ='Financial Statements'!J85-'Financial Statements'!I85 -> -31.85827 | D24: ='Financial Statements'!K85-'Financial Statements'!J85 -> 48.36705 | E24: ='Financial Statements'!L85-'Financial Statements'!K85 -> 119.14036 | F24: ='Financial Statements'!M85-'Financial Statements'!L85 -> 183.49287 | J24: Equity Value (in Cr) | K24: =K21-K22+K23 -> 14717.506
A25: Free Cash Flows | B25: =B21+B22-B23-B24 -> 1554.84 | C25: =C21+C22-C23-C24 -> 1149.0656 | D25: =D21+D22-D23-D24 -> 1215.4168 | E25: =E21+E22-E23-E24 -> 1308.8092 | F25: =F21+F22-F23-F24 -> 1428.3222 | G25: =F25*(1+G27)/(G26-G27) -> 16847.814 | J25: No. of share (in Cr.) | K25: =B11 -> 676.4
A26: WACC | B26: =$B$6 -> 0.13901679 | C26: =$B$6 -> 0.13901679 | D26: =$B$6 -> 0.13901679 | E26: =$B$6 -> 0.13901679 | F26: =$B$6 -> 0.13901679 | G26: =$B$6 -> 0.13901679 | J26: Intrincsic value of share | K26: =K24/K25 -> 21.758584
A27: Growth | G27: =B7 -> 0.05 | J27: Current share price | K27: =B10 -> 420
A28: Discounting Factor | B28: =1/(1+B26)^B17 -> 0.87795018 | C28: =1/(1+C26)^C17 -> 0.77079652 | D28: =1/(1+D26)^D17 -> 0.67672095 | E28: =1/(1+E26)^E17 -> 0.59412728 | F28: =1/(1+F26)^F17 -> 0.52161415 | G28: =1/(1+G26)^F17 -> 0.52161415 | J28: No of shares | K28: =B11 -> 676.4
A29: PV of Free Cash Flow | B29: =B25*B28 -> 1365.072 | C29: =C25*C28 -> 885.69578 | D29: =D25*D28 -> 822.49801 | E29: =E25*E28 -> 777.59924 | F29: =F25*F28 -> 745.0331 | G29: =G28*G25 -> 8788.0582 | J29: Market capitalization (in Cr) | K29: =K28*K27 -> 284088
G31: SENSTIVITY ANALSYSIS
A32: Market Value vs Fair Value | F32: WACC → | G32: =K26 -> 21.758584 | H32: 0.12 | I32: 0.13 | J32: 0.14 | K32: 0.15 | L32: 0.16
A33: CMP | B33: =B10 -> 420 | F33: g ↓ | G33: 0.04 | H33: 24.661838 | I33: 22.158461 | J33: 20.156297 | K33: 18.518609 | L33: 17.154242
A34: Upside Potential | B34: =B35-B33 -> -398.24142 | G34: 0.05 | H34: 27.058256 | I34: 23.957234 | J34: 21.545484 | K34: 19.616195 | L34: 18.037762
A35: Fair Value | B35: =K26 -> 21.758584 | G35: 0.06 | H35: 30.253479 | I35: 26.269942 | J35: 23.281968 | K35: 20.957689 | L35: 19.097987
A36: Upside Potential % | B36: =B34/B33 -> -0.94819385 | G36: 0.07 | H36: 34.726792 | I36: 29.353553 | J36: 25.51459 | K36: 22.634557 | L36: 20.393818
A37: Nature | B37: Over valued | G37: 0.08 | H37: 41.436761 | I37: 33.670608 | J37: 28.491419 | K37: 24.790529 | L37: 22.013605
A38: Recommendation | B38: Sell / Avoid

Sheet Relative Valuation
A1: RELATIVE VALUATION
A3: Company | B3: Market Data | F3: Financial Data | J3: Valuation Ratios
A4: Company | B4: Price (₹) | C4: No. of Shares (in Cr.) | D4: Market Cap (in Cr) | E4: Enterprise Value (in Cr) | F4: Sales (in Cr) | G4: EBITDA (in Cr) | H4: EBIT (in Cr) | I4: EPS (₹) | J4: P/E | K4: EV/Sales | L4: EV/EBITDA | M4: EV/EBIT | N4: Net Debt (in Cr) | O4: D&A (in Cr)
A5: ITC Ltd | B5: 470 | C5: 12457 | D5: =B5*C5 -> 5854790 | E5: =D5+N5 -> 5819790 | F5: 75000 | G5: 27225 | H5: 23400 | I5: 12.1 | J5: =B5/I5 -> 38.842975 | K5: =E5/F5 -> 77.5972 | L5: =E5/G5 -> 213.76639 | M5: =E5/H5 -> 248.70897 | N5: -35000 | O5: 850
A6: Nestle India | B6: 2250 | C6: 964 | D6: =B6*C6 -> 2169000 | E6: =D6+N6 -> 2167800 | F6: 21000 | G6: 5271 | H6: 4578 | I6: 128.3 | J6: =B6/I6 -> 17.537023 | K6: =E6/F6 -> 103.22857 | L6: =E6/G6 -> 411.26921 | M6: =E6/H6 -> 473.52556 | N6: -1200 | O6: 310
A7: Britannia Industries | B7: 5400 | C7: 241 | D7: =B7*C7 -> 1301400 | E7: =D7+N7 -> 1301820 | F7: 18200 | G7: 3058 | H7: 2748 | I7: 82.4 | J7: =B7/I7 -> 65.533981 | K7: =E7/F7 -> 71.528571 | L7: =E7/G7 -> 425.70961 | M7: =E7/H7 -> 473.73362 | N7: 420 | O7: 220
A8: HUL | B8: 2350 | C8: 2355 | D8: =B8*C8 -> 5534250 | E8: =D8+N8 -> 5526050 | F8: 65000 | G8: 15925 | H8: 14235 | I8: 42.8 | J8: =B8/I8 -> 54.906542 | K8: =E8/F8 -> 85.016154 | L8: =E8/G8 -> 347.00471 | M8: =E8/H8 -> 388.20162 | N8: -8200 | O8: 1200
A10: Average Data | J10: =AVERAGE(J5:J8) -> 44.20513 | K10: =AVERAGE(K5:K8) -> 84.342624 | L10: =AVERAGE(L5:L8) -> 349.43748 | M10: =AVERAGE(M5:M8) -> 396.04244
A11: Median Data | J11: =MEDIAN(J5:J8) -> 46.874759 | K11: =MEDIAN(K5:K8) -> 81.306677 | L11: =MEDIAN(L5:L8) -> 379.13696 | M11: =MEDIAN(M5:M8) -> 430.86359

Sheet All Ratio Forecasr
A1: RATIOS
A3: Growth | B3: 2019 Actual | C3: 2020 Actual | D3: 2021 Actual | E3: 2022 Actual | F3: 2023 Actual | G3: 2024 Actual | H3: 2025 Actual | I3: 2026 Forecast | J3: 2027 Forecast | K3: 2028 Forecast | L3: 2029 Forecast
A4: Operating Income (%) | B4: =('Financial Statements'!D8-'Financial Statements'!C8)/'Financial Statements'!C8 -> 0.35257 | C4: =('Financial Statements'!E8-'Financial Statements'!D8)/'Financial Statements'!D8 -> 0.60646569 | D4: =('Financial Statements'!F8-'Financial Statements'!E8)/'Financial Statements'!E8 -> 0.19224544 | E4: =('Financial Statements'!G8-'Financial Statements'!F8)/'Financial Statements'!F8 -> 0.13581834 | F4: =('Financial Statements'!H8-'Financial Statements'!G8)/'Financial Statements'!G8 -> 0.01451152 | G4: =('Financial Statements'!I8-'Financial Statements'!H8)/'Financial Statements'!H8 -> 0.12 | H4: =('Financial Statements'!J8-'Financial Statements'!I8)/'Financial Statements'!I8 -> 0.12 | I4: =('Financial Statements'!K8-'Financial Statements'!J8)/'Financial Statements'!J8 -> 0.12 | ... K4: =('Financial Statements'!M8-'Financial Statements'!L8)/'Financial Statements'!L8 -> 0.12 | L4: =('Financial Statements'!#REF!-'Financial Statements'!M8)/'Financial Statements'!M8 -> #REF!
A5: EBITDA (%) | B5: =('Financial Statements'!D22-'Financial Statements'!C22)/'Financial Statements'!C22 -> 0.43013461 | C5: =('Financial Statements'!E22-'Financial Statements'!D22)/'Financial Statements'!D22 -> 0.87745918 | D5: =('Financial Statements'!F22-'Financial Statements'!E22)/'Financial Statements'!E22 -> 0.34736525 | E5: =('Financial Statements'!G22-'Financial Statements'!F22)/'Financial Statements'!F22 -> 0.29081043 | F5: =('Financial Statements'!H22-'Financial Statements'!G22)/'Financial Statements'!G22 -> 0.058751191 | G5: =('Financial Statements'!I22-'Financial Statements'!H22)/'Financial Statements'!H22 -> -0.13261322 | H5: =('Financial Statements'!J22-'Financial Statements'!I22)/'Financial Statements'!I22 -> 0.12 | I5: =('Financial Statements'!K22-'Financial Statements'!J22)/'Financial Statements'!J22 -> 0.12 | ... K5: =('Financial Statements'!M22-'Financial Statements'!L22)/'Financial Statements'!L22 -> 0.12 | L5: =('Financial Statements'!#REF!-'Financial Statements'!M22)/'Financial Statements'!M22 -> #REF!
A6: Adj PAT (%) | B6: =('Financial Statements'!D32-'Financial Statements'!C32)/'Financial Statements'!C32 -> 1.1617719 | C6: =('Financial Statements'!E32-'Financial Statements'!D32)/'Financial Statements'!D32 -> 1.5949458 | D6: =('Financial Statements'!F32-'Financial Statements'!E32)/'Financial Statements'!E32 -> 0.39752008 | E6: =('Financial Statements'!G32-'Financial Statements'!F32)/'Financial Statements'!F32 -> 0.30714934 | F6: =('Financial Statements'!H32-'Financial Statements'!G32)/'Financial Statements'!G32 -> 0.15354514 | G6: =('Financial Statements'!I32-'Financial Statements'!H32)/'Financial Statements'!H32 -> -0.1602437 | H6: =('Financial Statements'!J32-'Financial Statements'!I32)/'Financial Statements'!I32 -> 0.10629718 | I6: =('Financial Statements'!K32-'Financial Statements'!J32)/'Financial Statements'!J32 -> 0.10701941 | ... K6: =('Financial Statements'!M32-'Financial Statements'!L32)/'Financial Statements'!L32 -> 0.10867783 | L6: =('Financial Statements'!#REF!-'Financial Statements'!M32)/'Financial Statements'!M32 -> #REF!
A7: Adj EPS (%) | B7: =('Financial Statements'!D37-'Financial Statements'!C37)/'Financial Statements'!C37 -> 0.44132653 | C7: =('Financial Statements'!E37-'Financial Statements'!D37)/'Financial Statements'!D37 -> 0.73097345 | D7: =('Financial Statements'!F37-'Financial Statements'!E37)/'Financial Statements'!E37 -> -0.30163599 | E7: =('Financial Statements'!G37-'Financial Statements'!F37)/'Financial Statements'!F37 -> -0.49780381 | F7: =('Financial Statements'!H37-'Financial Statements'!G37)/'Financial Statements'!G37 -> 0.15306122 | G7: =('Financial Statements'!I37-'Financial Statements'!H37)/'Financial Statements'!H37 -> -0.1602437 | H7: =('Financial Statements'!J37-'Financial Statements'!I37)/'Financial Statements'!I37 -> 0.10629718 | I7: =('Financial Statements'!K37-'Financial Statements'!J37)/'Financial Statements'!J37 -> 0.10701941 | ... K7: =('Financial Statements'!M37-'Financial Statements'!L37)/'Financial Statements'!L37 -> 0.10867783 | L7: =('Financial Statements'!#REF!-'Financial Statements'!M37)/'Financial Statements'!M37 -> #REF!
A9: Profitability | B9: 2019 Actual | C9: 2020 Actual | D9: 2021 Actual | E9: 2022 Actual | F9: 2023 Actual | G9: 2024 Actual | H9: 2025 Actual | I9: 2026 Forecast | J9: 2027 Forecast | K9: 2028 Forecast | L9: 2029 Forecast
A10: EBITDA Margin (%) | B10: ='Financial Statements'!C22/'Financial Statements'!C8 -> 0.17747542 | C10: ='Financial Statements'!D22/'Financial Statements'!D8 -> 0.18765294 | D10: ='Financial Statements'!E22/'Financial Statements'!E8 -> 0.21930797 | E10: ='Financial Statements'!F22/'Financial Statements'!F8 -> 0.24784154 | F10: ='Financial Statements'!G22/'Financial Statements'!G8 -> 0.28166163 | G10: ='Financial Statements'!H22/'Financial Statements'!H8 -> 0.29394401 | H10: ='Financial Statements'!I22/'Financial Statements'!I8 -> 0.22764567 | I10: ='Financial Statements'!J22/'Financial Statements'!J8 -> 0.22764567 | ... L10: ='Financial Statements'!M22/'Financial Statements'!M8 -> 0.22764567
A11: Operating Income | B11: ='Financial Statements'!C22 -> 865.45 | C11: ='Financial Statements'!D22 -> 1237.71 | D11: ='Financial Statements'!E22 -> 2323.75 | E11: ='Financial Statements'!F22 -> 3130.94 | F11: ='Financial Statements'!G22 -> 4041.45 | G11: ='Financial Statements'!H22 -> 4278.89 | H11: ='Financial Statements'!I22 -> 3711.4526 | I11: ='Financial Statements'!J22 -> 4156.827 | ... L11: ='Financial Statements'!M22 -> 5840.0426
A12: EBIT Margin (%) | B12: ='Financial Statements'!C27 -> 0.12621887 | C12: ='Financial Statements'!D27 -> 0.16394825 | D12: ='Financial Statements'!E27 -> 0.20457387 | E12: ='Financial Statements'!F27 -> 0.22849116 | F12: ='Financial Statements'!G27 -> 0.25701811 | G12: ='Financial Statements'!H27 -> 0.29166192 | H12: ='Financial Statements'!I27 -> 0.17614435 | I12: ='Financial Statements'!J27 -> 0.17340359 | ... L12: ='Financial Statements'!M27 -> 0.16682074
A13: PAT | B13: ='Financial Statements'!C32 -> 226.43 | C13: ='Financial Statements'!D32 -> 489.49 | D13: ='Financial Statements'!E32 -> 1270.2 | E13: ='Financial Statements'!F32 -> 1775.13 | F13: ='Financial Statements'!G32 -> 2320.36 | G13: ='Financial Statements'!H32 -> 2676.64 | H13: ='Financial Statements'!I32 -> 2247.7253 | I13: ='Financial Statements'!J32 -> 2486.6522 | ... L13: ='Financial Statements'!M32 -> 3381.0221
A14: PAT Margin (%) | B14: ='Financial Statements'!C33 -> 0.046433369 | C14: ='Financial Statements'!D33 -> 0.074213053 | D14: ='Financial Statements'!E33 -> 0.11987735 | E14: ='Financial Statements'!F33 -> 0.14051721 | F14: ='Financial Statements'!G33 -> 0.16171334 | G14: ='Financial Statements'!H33 -> 0.18387532 | H14: ='Financial Statements'!I33 -> 0.13786648 | I14: ='Financial Statements'!J33 -> 0.13617973 | ... L14: ='Financial Statements'!M33 -> 0.13179271
A15: ROE (%) | B15: ='Financial Statements'!C32/'Financial Statements'!C47 -> 0.056441421 | C15: ='Financial Statements'!D32/'Financial Statements'!D47 -> 0.11128263 | D15: ='Financial Statements'!E32/'Financial Statements'!E47 -> 0.23021713 | E15: ='Financial Statements'!F32/'Financial Statements'!F47 -> 0.25088581 | F15: ='Financial Statements'!G32/'Financial Statements'!G47 -> 0.14012927 | G15: ='Financial Statements'!H32/'Financial Statements'!H47 -> 0.14264359 | H15: ='Financial Statements'!I32/'Financial Statements'!I47 -> 0.10819741 | I15: ='Financial Statements'!J32/'Financial Statements'!J47 -> 0.10812612 | ... L15: ='Financial Statements'!M32/'Financial Statements'!M47 -> 0.10833523
A16: ROCE (%) | B16: ='Financial Statements'!C32/('Financial Statements'!C67-'Financial Statements'!C55) -> 0.035440878 | C16: ='Financial Statements'!D32/('Financial Statements'!D67-'Financial Statements'!D55) -> 0.07396198 | D16: ='Financial Statements'!E32/('Financial Statements'!E67-'Financial Statements'!E55) -> 0.162833 | E16: ='Financial Statements'!F32/('Financial Statements'!F67-'Financial Statements'!F55) -> 0.16564426 | F16: ='Financial Statements'!G32/('Financial Statements'!G67-'Financial Statements'!G55) -> 0.13404234 | G16: ='Financial Statements'!H32/('Financial Statements'!H67-'Financial Statements'!H55) -> 0.13571071 | H16: ='Financial Statements'!I32/('Financial Statements'!I67-'Financial Statements'!I55) -> 0.1037389 | I16: ='Financial Statements'!J32/('Financial Statements'!J67-'Financial Statements'!J55) -> 0.1042334 | ... L16: ='Financial Statements'!M32/('Financial Statements'!M67-'Financial Statements'!M55) -> 0.10567841
A18: Valuations | B18: 2019 Actual | C18: 2020 Actual | D18: 2021 Actual | E18: 2022 Actual | F18: 2023 Actual | G18: 2024 Actual | H18: 2025 Actual | I18: 2026 Forecast | J18: 2027 Forecast | K18: 2028 Forecast | L18: 2029 Forecast
